<?xml version="1.0" encoding="UTF-8"?>
<testng-results skipped="0" failed="1" total="1" passed="0">
  <reporter-output>
  </reporter-output>
  <suite name="InternetBankingV1" duration-ms="71601" started-at="2022-01-13T14:33:12Z" finished-at="2022-01-13T14:34:24Z">
    <groups>
    </groups>
    <test name="BankingApp Test" duration-ms="71601" started-at="2022-01-13T14:33:12Z" finished-at="2022-01-13T14:34:24Z">
      <class name="com.inetbanking.testCases.TC_LoginTest">
        <test-method status="PASS" signature="setUp(java.lang.String)[pri:0, instance:com.inetbanking.testCases.TC_LoginTest@3cbbc1e0]" name="setUp" is-config="true" duration-ms="31016" started-at="2022-01-13T20:03:12Z" finished-at="2022-01-13T20:03:44Z">
          <params>
            <param index="0">
              <value>
                <![CDATA[chrome]]>
              </value>
            </param>
          </params>
          <reporter-output>
          </reporter-output>
        </test-method> <!-- setUp -->
        <test-method status="FAIL" signature="loginTest()[pri:0, instance:com.inetbanking.testCases.TC_LoginTest@3cbbc1e0]" name="loginTest" duration-ms="36452" started-at="2022-01-13T20:03:44Z" finished-at="2022-01-13T20:04:20Z">
          <exception class="java.lang.AssertionError">
            <message>
              <![CDATA[expected [true] but found [false]]]>
            </message>
            <full-stacktrace>
              <![CDATA[java.lang.AssertionError: expected [true] but found [false]
	at org.testng.Assert.fail(Assert.java:94)
	at org.testng.Assert.failNotEquals(Assert.java:513)
	at org.testng.Assert.assertTrue(Assert.java:42)
	at org.testng.Assert.assertTrue(Assert.java:52)
	at com.inetbanking.testCases.TC_LoginTest.loginTest(TC_LoginTest.java:29)
	at sun.reflect.NativeMethodAccessorImpl.invoke0(Native Method)
	at sun.reflect.NativeMethodAccessorImpl.invoke(NativeMethodAccessorImpl.java:62)
	at sun.reflect.DelegatingMethodAccessorImpl.invoke(DelegatingMethodAccessorImpl.java:43)
	at java.lang.reflect.Method.invoke(Method.java:498)
	at org.testng.internal.MethodInvocationHelper.invokeMethod(MethodInvocationHelper.java:86)
	at org.testng.internal.Invoker.invokeMethod(Invoker.java:645)
	at org.testng.internal.Invoker.invokeTestMethod(Invoker.java:822)
	at org.testng.internal.Invoker.invokeTestMethods(Invoker.java:1130)
	at org.testng.internal.TestMethodWorker.invokeTestMethods(TestMethodWorker.java:129)
	at org.testng.internal.TestMethodWorker.run(TestMethodWorker.java:112)
	at org.testng.TestRunner.privateRun(TestRunner.java:782)
	at org.testng.TestRunner.run(TestRunner.java:632)
	at org.testng.SuiteRunner.runTest(SuiteRunner.java:366)
	at org.testng.SuiteRunner.runSequentially(SuiteRunner.java:361)
	at org.testng.SuiteRunner.privateRun(SuiteRunner.java:319)
	at org.testng.SuiteRunner.run(SuiteRunner.java:268)
	at org.testng.SuiteRunnerWorker.runSuite(SuiteRunnerWorker.java:52)
	at org.testng.SuiteRunnerWorker.run(SuiteRunnerWorker.java:86)
	at org.testng.TestNG.runSuitesSequentially(TestNG.java:1244)
	at org.testng.TestNG.runSuitesLocally(TestNG.java:1169)
	at org.testng.TestNG.run(TestNG.java:1064)
	at org.testng.remote.RemoteTestNG.run(RemoteTestNG.java:113)
	at org.testng.remote.RemoteTestNG.initAndRun(RemoteTestNG.java:206)
	at org.testng.remote.RemoteTestNG.main(RemoteTestNG.java:177)
]]>
            </full-stacktrace>
          </exception> <!-- java.lang.AssertionError -->
          <reporter-output>
          </reporter-output>
        </test-method> <!-- loginTest -->
        <test-method status="PASS" signature="tearDowm()[pri:0, instance:com.inetbanking.testCases.TC_LoginTest@3cbbc1e0]" name="tearDowm" is-config="true" duration-ms="2657" started-at="2022-01-13T20:04:21Z" finished-at="2022-01-13T20:04:24Z">
          <reporter-output>
          </reporter-output>
        </test-method> <!-- tearDowm -->
      </class> <!-- com.inetbanking.testCases.TC_LoginTest -->
    </test> <!-- BankingApp Test -->
  </suite> <!-- InternetBankingV1 -->
</testng-results>
